<robot
  name="pumpkin_description">
  <link
    name="map">
    <visual>
      <origin
        xyz="0 0 0"
        rpy="0 0 0" />
      <geometry>
        <mesh
          filename="package://pumpkin_description/meshes/map.STL" />
      </geometry>
      <material
        name="">
        <color
          rgba="0.501960784313725 0.501960784313725 0.501960784313725 1" />
      </material>
    </visual>
    <collision>
      <origin
        xyz="0 0 0"
        rpy="0 0 0" />
      <geometry>
        <mesh
          filename="package://pumpkin_description/meshes/map.STL" />
      </geometry>
    </collision>
  </link>
  <link
    name="base_link">
    <inertial>
      <origin
        xyz="-0.29356 -0.175 0.45135"
        rpy="0 0 0" />
      <mass
        value="13.982" />
      <inertia
        ixx="2.3196"
        ixy="-8.3709E-17"
        ixz="0.0096879"
        iyy="2.4878"
        iyz="-1.5884E-16"
        izz="0.42458" />
    </inertial>
    <visual>
      <origin
        xyz="0 0 0"
        rpy="0 0 0" />
      <geometry>
        <mesh
          filename="package://pumpkin_description/meshes/base_link.STL" />
      </geometry>
      <material
        name="">
        <color
          rgba="0.50196 0.50196 0.50196 1" />
      </material>
    </visual>
    <collision>
      <origin
        xyz="0 0 0"
        rpy="0 0 0" />
      <geometry>
        <mesh
          filename="package://pumpkin_description/meshes/base_link.STL" />
      </geometry>
    </collision>
  </link>
  <joint
    name="map_base"
    type="fixed">
    <origin
      xyz="0 0 0"
      rpy="0 0 0" />
    <parent
      link="map" />
    <child
      link="base_link" />
    <axis
      xyz="0 0 0" />
  </joint>
  <link
    name="chest_link">
    <inertial>
      <origin
        xyz="0.07 0.086132 0.20644"
        rpy="0 0 0" />
      <mass
        value="10.022" />
      <inertia
        ixx="0.13958"
        ixy="2.3825E-08"
        ixz="-9.3686E-08"
        iyy="0.12652"
        iyz="0.020291"
        izz="0.051192" />
    </inertial>
    <visual>
      <origin
        xyz="0 0 0"
        rpy="0 0 0" />
      <geometry>
        <mesh
          filename="package://pumpkin_description/meshes/chest_link.STL" />
      </geometry>
      <material
        name="">
        <color
          rgba="1 0.50196 0 1" />
      </material>
    </visual>
    <collision>
      <origin
        xyz="0 0 0"
        rpy="0 0 0" />
      <geometry>
        <mesh
          filename="package://pumpkin_description/meshes/chest_link.STL" />
      </geometry>
    </collision>
  </link>
  <joint
    name="base_chest"
    type="fixed">
    <origin
      xyz="-0.225 -0.0975 1.061"
      rpy="0 0 3.1416" />
    <parent
      link="base_link" />
    <child
      link="chest_link" />
    <axis
      xyz="0 0 0" />
  </joint>
  <link
    name="neck1_link">
    <inertial>
      <origin
        xyz="2.7756E-17 0.0011458 0.014278"
        rpy="0 0 0" />
      <mass
        value="0.041592" />
      <inertia
        ixx="2.2923E-05"
        ixy="-1.468E-22"
        ixz="-3.102E-21"
        iyy="2.7209E-05"
        iyz="-8.5099E-07"
        izz="2.0902E-05" />
    </inertial>
    <visual>
      <origin
        xyz="0 0 0"
        rpy="0 0 0" />
      <geometry>
        <mesh
          filename="package://pumpkin_description/meshes/neck1_link.STL" />
      </geometry>
      <material
        name="">
        <color
          rgba="0.25098 0.25098 0.25098 1" />
      </material>
    </visual>
    <collision>
      <origin
        xyz="0 0 0"
        rpy="0 0 0" />
      <geometry>
        <mesh
          filename="package://pumpkin_description/meshes/neck1_link.STL" />
      </geometry>
    </collision>
  </link>
  <joint
    name="neck_0"
    type="revolute">
    <origin
      xyz="0.069268 0.042993 0.38107"
      rpy="1.8504E-15 0 0" />
    <parent
      link="chest_link" />
    <child
      link="neck1_link" />
    <axis
      xyz="0 0 1" />
    <limit
      lower="-2"
      upper="2"
      effort="0"
      velocity="0" />
    <safety_controller
      soft_upper="2"
      soft_lower="-2"
      k_velocity="0" />
  </joint>
  <link
    name="neck2_Link">
    <inertial>
      <origin
        xyz="-0.013186 1.4317E-05 0.01784"
        rpy="0 0 0" />
      <mass
        value="0.049043" />
      <inertia
        ixx="4.6998E-05"
        ixy="-3.8995E-09"
        ixz="9.5972E-16"
        iyy="4.876E-05"
        iyz="-1.0219E-18"
        izz="1.8765E-05" />
    </inertial>
    <visual>
      <origin
        xyz="0 0 0"
        rpy="0 0 0" />
      <geometry>
        <mesh
          filename="package://pumpkin_description/meshes/neck2_Link.STL" />
      </geometry>
      <material
        name="">
        <color
          rgba="0.25098 0.25098 0.25098 1" />
      </material>
    </visual>
    <collision>
      <origin
        xyz="0 0 0"
        rpy="0 0 0" />
      <geometry>
        <mesh
          filename="package://pumpkin_description/meshes/neck2_Link.STL" />
      </geometry>
    </collision>
  </link>
  <joint
    name="neck_1"
    type="revolute">
    <origin
      xyz="-0.018635 -0.0027867 0.0327"
      rpy="0 1.5708 0" />
    <parent
      link="neck1_link" />
    <child
      link="neck2_Link" />
    <axis
      xyz="0 0 -1" />
    <limit
      lower="-2"
      upper="2"
      effort="0"
      velocity="0" />
    <safety_controller
      soft_upper="2"
      soft_lower="-2"
      k_velocity="0" />
  </joint>
  <link
    name="head_link">
    <inertial>
      <origin
        xyz="-0.011175 0.088655 -4.2266E-12"
        rpy="0 0 0" />
      <mass
        value="2.4557" />
      <inertia
        ixx="0.015009"
        ixy="-0.0003677"
        ixz="3.2051E-13"
        iyy="0.011887"
        iyz="4.573E-13"
        izz="0.0056147" />
    </inertial>
    <visual>
      <origin
        xyz="0 0 0"
        rpy="0 0 0" />
      <geometry>
        <mesh
          filename="package://pumpkin_description/meshes/head_link.STL" />
      </geometry>
      <material
        name="">
        <color
          rgba="1 0.50196 0 1" />
      </material>
    </visual>
    <collision>
      <origin
        xyz="0 0 0"
        rpy="0 0 0" />
      <geometry>
        <mesh
          filename="package://pumpkin_description/meshes/head_link.STL" />
      </geometry>
    </collision>
  </link>
  <joint
    name="neck2_head"
    type="fixed">
    <origin
      xyz="-0.02824 0 0.01784"
      rpy="3.1416 2.6791E-16 -1.5708" />
    <parent
      link="neck2_Link" />
    <child
      link="head_link" />
    <axis
      xyz="0 0 0" />
  </joint>
  <link
    name="r_shoulder1_link">
    <inertial>
      <origin
        xyz="-0.044868 0.0029358 0.034803"
        rpy="0 0 0" />
      <mass
        value="0.9973" />
      <inertia
        ixx="0.0010727"
        ixy="-8.1153E-06"
        ixz="-0.00010634"
        iyy="0.002707"
        iyz="0.00011088"
        izz="0.0025815" />
    </inertial>
    <visual>
      <origin
        xyz="0 0 0"
        rpy="0 0 0" />
      <geometry>
        <mesh
          filename="package://pumpkin_description/meshes/r_shoulder1_link.STL" />
      </geometry>
      <material
        name="">
        <color
          rgba="0.75294 0.75294 0.75294 1" />
      </material>
    </visual>
    <collision>
      <origin
        xyz="0 0 0"
        rpy="0 0 0" />
      <geometry>
        <mesh
          filename="package://pumpkin_description/meshes/r_shoulder1_link.STL" />
      </geometry>
    </collision>
  </link>
  <joint
    name="r_shoulder_0"
    type="revolute">
    <origin
      xyz="-0.033 0.085 0.22432"
      rpy="1.5708 0 -1.5708" />
    <parent
      link="chest_link" />
    <child
      link="r_shoulder1_link" />
    <axis
      xyz="0 0 1" />
    <limit
      lower="-1.94"
      upper="1.94"
      effort="0"
      velocity="0" />
    <safety_controller
      soft_upper="1.93"
      soft_lower="-1.93"
      k_velocity="0" />
  </joint>
  <link
    name="r_shoulder2_link">
    <inertial>
      <origin
        xyz="0.0818108751825954 0.000268250221157729 0.0968293123319838"
        rpy="0 0 0" />
      <mass
        value="0.672221677129179" />
      <inertia
        ixx="0.0013811976922621"
        ixy="5.22942613640295E-06"
        ixz="-0.000156786157007318"
        iyy="0.0014318894742788"
        iyz="-7.15872684594063E-06"
        izz="0.000752973718100049" />
    </inertial>
    <visual>
      <origin
        xyz="0 0 0"
        rpy="0 0 0" />
      <geometry>
        <mesh
          filename="package://pumpkin_description/meshes/r_shoulder2_link.STL" />
      </geometry>
      <material
        name="">
        <color
          rgba="0.752941176470588 0.752941176470588 0.752941176470588 1" />
      </material>
    </visual>
    <collision>
      <origin
        xyz="0 0 0"
        rpy="0 0 0" />
      <geometry>
        <mesh
          filename="package://pumpkin_description/meshes/r_shoulder2_link.STL" />
      </geometry>
    </collision>
  </link>
  <joint
    name="r_shoulder_1"
    type="revolute">
    <origin
      xyz="0.0018931 0.04856 0.03917"
      rpy="1.5708 -0.80995 1.8385E-15" />
    <parent
      link="r_shoulder1_link" />
    <child
      link="r_shoulder2_link" />
    <axis
      xyz="0 0 -1" />
    <limit
      lower="-0.7"
      upper="0.7"
      effort="0"
      velocity="0" />
    <safety_controller
      soft_upper="0.69"
      soft_lower="-0.69"
      k_velocity="0" />
  </joint>
  <link
    name="r_upperarm_link">
    <inertial>
      <origin
        xyz="-0.00793665156246126 0 0.073948800226588"
        rpy="0 0 0" />
      <mass
        value="0.802460503767575" />
      <inertia
        ixx="0.00226084580510553"
        ixy="4.97663211092193E-21"
        ixz="-5.70402466352589E-05"
        iyy="0.00216004005879803"
        iyz="6.03936794981649E-19"
        izz="0.00065120931549201" />
    </inertial>
    <visual>
      <origin
        xyz="0 0 0"
        rpy="0 0 0" />
      <geometry>
        <mesh
          filename="package://pumpkin_description/meshes/r_upperarm_link.STL" />
      </geometry>
      <material
        name="">
        <color
          rgba="0.752941176470588 0.752941176470588 0.752941176470588 1" />
      </material>
    </visual>
    <collision>
      <origin
        xyz="0 0 0"
        rpy="0 0 0" />
      <geometry>
        <mesh
          filename="package://pumpkin_description/meshes/r_upperarm_link.STL" />
      </geometry>
    </collision>
  </link>
  <joint
    name="r_shoulder_2"
    type="revolute">
    <origin
      xyz="0.12866 0 0.0575"
      rpy="-1.5708 6.9696E-18 -1.5708" />
    <parent
      link="r_shoulder2_link" />
    <child
      link="r_upperarm_link" />
    <axis
      xyz="0 0 1" />
    <limit
      lower="-1.94"
      upper="1.94"
      effort="0"
      velocity="0" />
    <safety_controller
      soft_upper="1.93"
      soft_lower="-1.93"
      k_velocity="0" />
  </joint>
  <link
    name="r_forerarm_link">
    <inertial>
      <origin
        xyz="-0.00179614827927999 -0.105703334026338 0.0415800075385994"
        rpy="0 0 0" />
      <mass
        value="0.365895324563383" />
      <inertia
        ixx="0.000594532925991162"
        ixy="-2.57836475588205E-05"
        ixz="5.02805503823674E-12"
        iyy="0.000234655135698342"
        iyz="2.70713437303398E-10"
        izz="0.000592122956218473" />
    </inertial>
    <visual>
      <origin
        xyz="0 0 0"
        rpy="0 0 0" />
      <geometry>
        <mesh
          filename="package://pumpkin_description/meshes/r_forerarm_link.STL" />
      </geometry>
      <material
        name="">
        <color
          rgba="0.752941176470588 0.752941176470588 0.752941176470588 1" />
      </material>
    </visual>
    <collision>
      <origin
        xyz="0 0 0"
        rpy="0 0 0" />
      <geometry>
        <mesh
          filename="package://pumpkin_description/meshes/r_forerarm_link.STL" />
      </geometry>
    </collision>
  </link>
  <joint
    name="r_elbow"
    type="revolute">
    <origin
      xyz="0.032685 0 0.14623"
      rpy="-1.5708 2.3453E-16 1.5708" />
    <parent
      link="r_upperarm_link" />
    <child
      link="r_forerarm_link" />
    <axis
      xyz="0 0 1" />
    <limit
      lower="-1.53"
      upper="2.54"
      effort="0"
      velocity="0" />
    <safety_controller
      soft_upper="2.53"
      soft_lower="-1.52"
      k_velocity="0" />
  </joint>
  <link
    name="r_wrist0_link">
    <inertial>
      <origin
        xyz="0 0.00114575656464136 0.0142778615282853"
        rpy="0 0 0" />
      <mass
        value="0.0415918723991328" />
      <inertia
        ixx="2.2922511055698E-05"
        ixy="-3.07818243933704E-21"
        ixz="2.89393653639401E-21"
        iyy="2.7209357274431E-05"
        iyz="-8.50993382986105E-07"
        izz="2.09020496178278E-05" />
    </inertial>
    <visual>
      <origin
        xyz="0 0 0"
        rpy="0 0 0" />
      <geometry>
        <mesh
          filename="package://pumpkin_description/meshes/r_wrist0_link.STL" />
      </geometry>
      <material
        name="">
        <color
          rgba="0.250980392156863 0.250980392156863 0.250980392156863 1" />
      </material>
    </visual>
    <collision>
      <origin
        xyz="0 0 0"
        rpy="0 0 0" />
      <geometry>
        <mesh
          filename="package://pumpkin_description/meshes/r_wrist0_link.STL" />
      </geometry>
    </collision>
  </link>
  <joint
    name="r_wrist_0"
    type="revolute">
    <origin
      xyz="0.0015954 -0.17436 0.04158"
      rpy="1.5708 -1.2823E-16 2.7019E-17" />
    <parent
      link="r_forerarm_link" />
    <child
      link="r_wrist0_link" />
    <axis
      xyz="0 0 -1" />
    <limit
      lower="-1.54"
      upper="1.54"
      effort="0"
      velocity="0" />
    <safety_controller
      soft_upper="1.53"
      soft_lower="-1.53"
      k_velocity="0" />
  </joint>
  <link
    name="r_wrist1_link">
    <inertial>
      <origin
        xyz="1.43169092654549E-05 0.0131862520168467 0.0178400000014268"
        rpy="0 0 0" />
      <mass
        value="0.0490431894031824" />
      <inertia
        ixx="4.87604220320217E-05"
        ixy="3.89953211178513E-09"
        ixz="-3.00334209752469E-18"
        iyy="4.69979552417376E-05"
        iyz="-1.02287314459969E-15"
        izz="1.87649639686501E-05" />
    </inertial>
    <visual>
      <origin
        xyz="0 0 0"
        rpy="0 0 0" />
      <geometry>
        <mesh
          filename="package://pumpkin_description/meshes/r_wrist1_link.STL" />
      </geometry>
      <material
        name="">
        <color
          rgba="0.250980392156863 0.250980392156863 0.250980392156863 1" />
      </material>
    </visual>
    <collision>
      <origin
        xyz="0 0 0"
        rpy="0 0 0" />
      <geometry>
        <mesh
          filename="package://pumpkin_description/meshes/r_wrist1_link.STL" />
      </geometry>
    </collision>
  </link>
  <joint
    name="r_wrist_1"
    type="revolute">
    <origin
      xyz="0.018635 -0.0027867 0.0327"
      rpy="1.5708 -6.6613E-16 -1.5708" />
    <parent
      link="r_wrist0_link" />
    <child
      link="r_wrist1_link" />
    <axis
      xyz="0 0 1" />
    <limit
      lower="-1.75"
      upper="1"
      effort="0"
      velocity="0" />
    <safety_controller
      soft_upper="0.9"
      soft_lower="-1.74"
      k_velocity="0" />
  </joint>
  <link
    name="l_shoulder1_link">
    <inertial>
      <origin
        xyz="0.0448677861640269 0.00293576780963056 0.0348025086156694"
        rpy="0 0 0" />
      <mass
        value="0.997303293307218" />
      <inertia
        ixx="0.00107273488038204"
        ixy="8.1153002214355E-06"
        ixz="0.000106340673464381"
        iyy="0.00270697972935808"
        iyz="0.000110876688565299"
        izz="0.00258150868839317" />
    </inertial>
    <visual>
      <origin
        xyz="0 0 0"
        rpy="0 0 0" />
      <geometry>
        <mesh
          filename="package://pumpkin_description/meshes/l_shoulder1_link.STL" />
      </geometry>
      <material
        name="">
        <color
          rgba="0.752941176470588 0.752941176470588 0.752941176470588 1" />
      </material>
    </visual>
    <collision>
      <origin
        xyz="0 0 0"
        rpy="0 0 0" />
      <geometry>
        <mesh
          filename="package://pumpkin_description/meshes/l_shoulder1_link.STL" />
      </geometry>
    </collision>
  </link>
  <joint
    name="l_shoulder_0"
    type="revolute">
    <origin
      xyz="0.173 0.085 0.22432"
      rpy="1.5708 0 1.5708" />
    <parent
      link="chest_link" />
    <child
      link="l_shoulder1_link" />
    <axis
      xyz="0 0 1" />
    <limit
      lower="-2"
      upper="2"
      effort="0"
      velocity="0" />
    <safety_controller
      soft_upper="2"
      soft_lower="-2"
      k_velocity="0" />
  </joint>
  <link
    name="l_shoulder2_link">
    <inertial>
      <origin
        xyz="-0.0594978051549702 -0.0561524924563586 0.0968293133210927"
        rpy="0 0 0" />
      <mass
        value="0.672221657665173" />
      <inertia
        ixx="0.00140002186570999"
        ixy="2.50445551073081E-05"
        ixz="0.000118600806553884"
        iyy="0.00141306521082711"
        iyz="0.000102795881372251"
        izz="0.000752973680339135" />
    </inertial>
    <visual>
      <origin
        xyz="0 0 0"
        rpy="0 0 0" />
      <geometry>
        <mesh
          filename="package://pumpkin_description/meshes/l_shoulder2_link.STL" />
      </geometry>
      <material
        name="">
        <color
          rgba="0.752941176470588 0.752941176470588 0.752941176470588 1" />
      </material>
    </visual>
    <collision>
      <origin
        xyz="0 0 0"
        rpy="0 0 0" />
      <geometry>
        <mesh
          filename="package://pumpkin_description/meshes/l_shoulder2_link.STL" />
      </geometry>
    </collision>
  </link>
  <joint
    name="l_shoulder_1"
    type="revolute">
    <origin
      xyz="-0.0018931 0.04856 0.03917"
      rpy="1.5708 1.5708 0" />
    <parent
      link="l_shoulder1_link" />
    <child
      link="l_shoulder2_link" />
    <axis
      xyz="0 0 1" />
    <limit
      lower="-2"
      upper="2"
      effort="0"
      velocity="0" />
    <safety_controller
      soft_upper="2"
      soft_lower="-2"
      k_velocity="0" />
  </joint>
  <link
    name="l_upperarm_link">
    <inertial>
      <origin
        xyz="0.00793665156246123 1.11022302462516E-16 0.0739488002265878"
        rpy="0 0 0" />
      <mass
        value="0.802460503767576" />
      <inertia
        ixx="0.00226084580510553"
        ixy="-2.41190340865341E-20"
        ixz="5.70402466352595E-05"
        iyy="0.00216004005879804"
        iyz="-1.06466059625874E-19"
        izz="0.000651209315492011" />
    </inertial>
    <visual>
      <origin
        xyz="0 0 0"
        rpy="0 0 0" />
      <geometry>
        <mesh
          filename="package://pumpkin_description/meshes/l_upperarm_link.STL" />
      </geometry>
      <material
        name="">
        <color
          rgba="0.752941176470588 0.752941176470588 0.752941176470588 1" />
      </material>
    </visual>
    <collision>
      <origin
        xyz="0 0 0"
        rpy="0 0 0" />
      <geometry>
        <mesh
          filename="package://pumpkin_description/meshes/l_upperarm_link.STL" />
      </geometry>
    </collision>
  </link>
  <joint
    name="l_shoulder_2"
    type="revolute">
    <origin
      xyz="-0.093277 -0.088613 0.0575"
      rpy="-1.5708 -1.9127E-16 2.3306" />
    <parent
      link="l_shoulder2_link" />
    <child
      link="l_upperarm_link" />
    <axis
      xyz="0 0 1" />
    <limit
      lower="-2"
      upper="2"
      effort="0"
      velocity="0" />
    <safety_controller
      soft_upper="2"
      soft_lower="-2"
      k_velocity="0" />
  </joint>
  <link
    name="l_forearm_link">
    <inertial>
      <origin
        xyz="-0.105703334026408 -0.00179614827927199 0.041539992405777"
        rpy="0 0 0" />
      <mass
        value="0.365895324563534" />
      <inertia
        ixx="0.000234655134974953"
        ixy="-2.57836481029172E-05"
        ixz="-2.72885325305146E-10"
        iyy="0.000594532925262089"
        iyz="-6.98592614088043E-12"
        izz="0.000592122956213413" />
    </inertial>
    <visual>
      <origin
        xyz="0 0 0"
        rpy="0 0 0" />
      <geometry>
        <mesh
          filename="package://pumpkin_description/meshes/l_forearm_link.STL" />
      </geometry>
      <material
        name="">
        <color
          rgba="0.752941176470588 0.752941176470588 0.752941176470588 1" />
      </material>
    </visual>
    <collision>
      <origin
        xyz="0 0 0"
        rpy="0 0 0" />
      <geometry>
        <mesh
          filename="package://pumpkin_description/meshes/l_forearm_link.STL" />
      </geometry>
    </collision>
  </link>
  <joint
    name="l_elbow"
    type="revolute">
    <origin
      xyz="-0.032685 0 0.14623"
      rpy="0 1.5708 0" />
    <parent
      link="l_upperarm_link" />
    <child
      link="l_forearm_link" />
    <axis
      xyz="0 0 -1" />
    <limit
      lower="-2"
      upper="2"
      effort="0"
      velocity="0" />
    <safety_controller
      soft_upper="2"
      soft_lower="-2"
      k_velocity="0" />
  </joint>
  <link
    name="l_wrist0_link">
    <inertial>
      <origin
        xyz="-0.00114575656464119 -1.11022302462516E-16 0.0142778615282853"
        rpy="0 0 0" />
      <mass
        value="0.0415918723991328" />
      <inertia
        ixx="2.7209357274431E-05"
        ixy="2.20299798716062E-21"
        ixz="8.50993382986109E-07"
        iyy="2.29225110556979E-05"
        iyz="1.40156889395083E-21"
        izz="2.09020496178278E-05" />
    </inertial>
    <visual>
      <origin
        xyz="0 0 0"
        rpy="0 0 0" />
      <geometry>
        <mesh
          filename="package://pumpkin_description/meshes/l_wrist0_link.STL" />
      </geometry>
      <material
        name="">
        <color
          rgba="0.250980392156863 0.250980392156863 0.250980392156863 1" />
      </material>
    </visual>
    <collision>
      <origin
        xyz="0 0 0"
        rpy="0 0 0" />
      <geometry>
        <mesh
          filename="package://pumpkin_description/meshes/l_wrist0_link.STL" />
      </geometry>
    </collision>
  </link>
  <joint
    name="l_wrist_0"
    type="revolute">
    <origin
      xyz="-0.17436 0.0015954 0.04154"
      rpy="3.1416 1.5708 0" />
    <parent
      link="l_forearm_link" />
    <child
      link="l_wrist0_link" />
    <axis
      xyz="0 0 1" />
    <limit
      lower="-2"
      upper="2"
      effort="0"
      velocity="0" />
    <safety_controller
      soft_upper="2"
      soft_lower="-2"
      k_velocity="0" />
  </joint>
  <link
    name="l_wrist1_link">
    <inertial>
      <origin
        xyz="1.43169092669815E-05 0.0131862520168656 -0.0178399999985557"
        rpy="0 0 0" />
      <mass
        value="0.0490431894031825" />
      <inertia
        ixx="4.87604220320218E-05"
        ixy="3.89953211114986E-09"
        ixz="-2.57809788956915E-18"
        iyy="4.69979552417377E-05"
        iyz="-1.02175324030821E-15"
        izz="1.87649639686501E-05" />
    </inertial>
    <visual>
      <origin
        xyz="0 0 0"
        rpy="0 0 0" />
      <geometry>
        <mesh
          filename="package://pumpkin_description/meshes/l_wrist1_link.STL" />
      </geometry>
      <material
        name="">
        <color
          rgba="0.250980392156863 0.250980392156863 0.250980392156863 1" />
      </material>
    </visual>
    <collision>
      <origin
        xyz="0 0 0"
        rpy="0 0 0" />
      <geometry>
        <mesh
          filename="package://pumpkin_description/meshes/l_wrist1_link.STL" />
      </geometry>
    </collision>
  </link>
  <joint
    name="l_wrist_1"
    type="revolute">
    <origin
      xyz="0.0027867 -0.018635 0.0327"
      rpy="1.5708 -6.6613E-16 -5.1638E-17" />
    <parent
      link="l_wrist0_link" />
    <child
      link="l_wrist1_link" />
    <axis
      xyz="0 0 1" />
    <limit
      lower="-2"
      upper="2"
      effort="0"
      velocity="0" />
    <safety_controller
      soft_upper="2"
      soft_lower="-2"
      k_velocity="0" />
  </joint>
</robot>